Workbook

Sheet 📖 ĐỊNH NGHĨA CHỈ SỐ
A1: 📖 ĐỊNH NGHĨA CHỈ SỐ — CARASE FB & STORE MASTER TRACKER (Cập nhật T8/2026)
A2: ⚠️ ĐỌC KỸ TRƯỚC KHI LÀM BÁO CÁO — Cột NGUỒN = fill_daily.py / metrics_script / Nhập tay. Dùng đúng công thức ghi trong cột này.
A3: 🟢 NGUỒN fill_daily.py = DT FB / Đơn FB / DT Store / Đơn Store / DT O3 / DT Tổng | 🟡 NGUỒN metrics_script = KH mới/cũ / Retention / CLV / Tần suất / Win-back | 🟠 Nhập tay = Ads / CMT+IB
A4: Row MASTER | B4: Kênh | C4: Tên chỉ số | D4: Định nghĩa đầy đủ | E4: ⚠️ CÔNG THỨC ĐÚNG (duy nhất được dùng) | F4: 🔴 NGUỒN LẤY SỐ | G4: Cách đọc & Ý nghĩa | H4: Ngưỡng / Tham chiếu T8/26 (FINAL 1/8–30/8)
A5: 📦 DOANH THU & ĐƠN HÀNG — FACEBOOK
A6: R6 | B6: FB | C6: Doanh thu FB | D6: Tổng tiền thu từ đơn FB giao thành công trong tháng, đã trừ đơn trả hàng. | E6: Σ (Tổng thu + Tiền CK) của đơn FB có 'Ngày thành công' trong tháng T. ⚠️ Phải cộng CẢ 2 cột — đơn CK có Tổng thu=0 → bỏ cột CK sẽ thiếu ~45% DT. ⚠️ ffill cột ID, 'Loại đơn', 'Ngày thành công' trước khi filter. ⚠️ Bỏ đơn có 'Loại đơn' chứa 'tra lai'/'tra hang'/'khach tra' (sau khi norm dấu). | F6: 🟢 fill_daily.py (cột DT FB trong DAILY sheet) | G6: Chỉ số DT chính kênh FB. So với target và ROAS. Dùng fill_daily — KHÔNG lấy từ metrics_script. | H6: T8/26 FINAL: 1,111,065,648đ Target: 1,292,244,677đ → 86.0%
A7: R7 | B7: FB | C7: Đơn hàng FB | D7: Số đơn FB giao thành công trong tháng, đã trừ đơn trả. | E7: COUNT DISTINCT ID đơn FB với 'Ngày thành công' trong T, 'Loại đơn' ≠ trả. ⚠️ ffill ID và 'Loại đơn' trước khi đếm. | F7: 🟢 fill_daily.py | G7: Kết hợp với DT FB tính AOV. Đơn tăng mà DT không tăng → AOV đang giảm. | H7: T8/26 FINAL: 2,549 đơn
A8: R8 | B8: FB | C8: AOV FB | D8: Giá trị đơn hàng trung bình kênh Facebook. | E8: DT FB ÷ Đơn FB (tính từ 2 chỉ số fill_daily — không tính riêng trong script) | F8: 🟢 Tính từ fill_daily = R6 ÷ R7 | G8: Giảm đột ngột = kiểm tra mix SP hoặc promotion mạnh. | H8: T8/26 FINAL: 435,883đ
A9: R9 | B9: FB | C9: CMT + Inbox Vpage | D9: Tổng comment + inbox trên Fanpage FB trong tháng. | E9: Nhập tay từ phần mềm fanpage / báo cáo nội bộ. Không lấy từ Nhanh.vn. | F9: 🟠 Nhập tay (từ phần mềm fanpage) | G9: Tử số CR%. Tăng nhưng CR giảm → content kéo traffic kém chất lượng. | H9: Benchmark CR%: 35–55%
A10: R11 | B10: FB | C10: CR% (Đơn FB / CMT+IB) | D10: Tỷ lệ chuyển đổi tương tác → đơn hàng. | E10: Đơn FB ÷ CMT+IB | F10: 🟢 Tính từ fill_daily + nhập tay R9 | G10: CR% <30% = chốt sale yếu. >60% = đang reach đúng tệp.
A11: 👤 KHÁCH HÀNG — FACEBOOK
A12: R15 | B12: FB | C12: KH mới FB | D12: Số SĐT mua đơn FB trong T chưa từng mua FB trước T_START (tính từ T6/2024). | E12: COUNT DISTINCT SĐT đơn FB trong T, SĐT KHÔNG có trong pkl FB với _date < T_START. ⚠️ lstrip('0') SĐT khi so sánh với pkl. ⚠️ ffill SĐT trước khi groupby. | F12: 🟡 metrics_script (phone match vs pkl FB) | G12: Nguồn tăng trưởng. KH mới ≥20% tổng KH FB là tốt. | H12: T8/26 FINAL: 722 KH
A13: R16 | B13: FB | C13: AOV lần đầu FB | D13: Tổng DT của KH mới trong T ÷ số KH mới (tính tất cả đơn của họ trong tháng T). | E13: Σ DT đơn của KH mới trong T ÷ COUNT KH mới | F13: 🟡 metrics_script | G13: Bình thường thấp hơn AOV KH cũ. Nếu AOV mới > AOV cũ → cần kiểm tra lại phân loại.
A14: R17 | B14: FB | C14: Activation Rate FB (Cách B) | D14: % KH có first purchase trong 90 ngày trước T_START, mua lần 2 trong tháng T, gap first→T ≤ 90 ngày. Denominator = KH mới trong cửa sổ [T_START-90d, T_START), không phải T-3 cố định. | E14: R17 — Activation Rate FB — CÁCH B (áp dụng từ T8/2026, tính lại hết T1/2025) DENOMINATOR: KH có first_ever_purchase trong [T_START − 90 ngày, T_START) = KH mới trong cửa sổ 90 ngày ngay trước tháng T NUMERATOR: Trong denominator đó, KH nào: (1) mua trong tháng T (2) đây đúng là lần mua THỨ 2 (prior_count == 1 trong lịch sử < T_START) (3) gap = ngày mua T − ngày first_ever ≤ 90 ngày ⚠️ KHÔNG dùng T-3 tháng cố định — window là 90 ngày trượt trước T_START ⚠️ prior_count đếm từ lịch sử (hist_ord), không phải từ data tháng T ⚠️ Denominator cố định theo T_START — không thay đổi dù T_END thay đổi | F14: 🟡 metrics_script (Cách B — 90-day window) | G14: Đo sức khỏe onboarding CRM. Mục tiêu ≥5%. <3% cần cải thiện hậu mãi lần 1. | H14: T8/26 FINAL: 115/2,124 = 5.42% (Cách B — window 90d trước T_START)
A15: R18 | B15: FB | C15: Cohort T-1→T (mua lại tháng tiếp theo) | D15: % KH mới tháng T-1 có ít nhất 1 đơn FB trong tháng T. | E15: COUNT(KH mới T-1 có đơn FB trong T) ÷ COUNT(tổng KH mới T-1) | F15: 🟡 metrics_script | G15: Tỷ lệ giữ chân tháng tiếp theo. 5–12% bình thường. >15% rất tốt. | H15: T8/26 FINAL: 74/823 = 8.99% (cohort KH mới T7)
A16: R20 | B16: FB | C16: KH cũ FB mua lại | D16: Số SĐT có đơn FB trong T VÀ đã có đơn FB trước T_START. | E16: COUNT DISTINCT SĐT đơn FB trong T, SĐT CÓ trong pkl FB với _date < T_START | F16: 🟡 metrics_script | G16: Nguồn DT ổn định, chi phí acquisition = 0. Mục tiêu chiếm 65–75% tổng KH FB. | H16: T8/26 FINAL: 1,615 KH
A17: R21 | B17: FB | C17: AOV KH cũ FB ← dùng tính CLV | D17: Tổng DT của KH cũ trong T ÷ số KH cũ. ⚠️ ĐÂY LÀ GIÁ TRỊ QUAN TRỌNG — dùng để tính CLV 12M và CLV realized. | E17: Σ DT đơn của KH cũ trong T ÷ COUNT KH cũ ⚠️ Tính theo customer (mỗi KH cộng dồn tất cả đơn trong T), không phải per đơn. | F17: 🟡 metrics_script | G17: KH cũ thường AOV cao hơn KH mới. AOV cũ < AOV mới là bất thường — kiểm tra phân loại. | H17: T8/26 FINAL: 496,244đ
A18: R22 | B18: FB | C18: % Retention FB | D18: Tỷ lệ KH cũ trong tổng KH FB tháng T. | E18: KH cũ FB ÷ (KH mới FB + KH cũ FB) | F18: 🟡 Tính từ R15+R20 | G18: Target: 65–75%. Dưới 60% = đang phụ thuộc nhiều vào KH mới. | H18: T8/26 FINAL: 69.11%
A19: R23 | B19: FB | C19: ↳ Mua lại ≤30 ngày | D19: KH cũ FB trong T có ngày mua cuối trước T_START cách T_START ≤30 ngày. | E19: COUNT KH cũ FB trong T, (T_START − max(_date trước T_START)) ≤ 30 | F19: 🟡 metrics_script | G19: Nhóm "nóng" nhất — lens 1 tháng quay đúng chu kỳ. | H19: T8/26 FINAL: 480 KH
A20: R25 | B20: FB | C20: ↳ Mua lại 31–90 ngày | D20: KH cũ FB trong T có ngày mua cuối cách T_START 31–90 ngày. | E20: COUNT KH cũ FB trong T, 31 ≤ (T_START − max(_date trước T_START)) ≤ 90 | F20: 🟡 metrics_script | G20: Core nhóm lens 1M/3M. Đây là tệp RFM chiến lược. | H20: T8/26 FINAL: 467 KH
A21: R27 | B21: FB | C21: ↳ Mua lại >90 ngày | D21: KH cũ FB trong T có ngày mua cuối cách T_START >90 ngày. | E21: COUNT KH cũ FB trong T, (T_START − max(_date trước T_START)) > 90 | F21: 🟡 metrics_script | G21: Semi-dormant tự quay lại. Nếu nhiều hơn ≤30d → KH đang drift về chu kỳ dài hơn. | H21: T8/26 FINAL: 668 KH
A22: R30 | B22: FB | C22: KH FB mua lần 3+ | D22: Số KH trong T đã có ≥3 đơn tích lũy trên kênh FB (tính đến cuối T). | E22: COUNT KH trong T, tổng đơn FB (pkl + data tháng T) ≥ 3 | F22: 🟡 metrics_script | G22: Nhóm trung thành thực sự. Nền tảng VIP program. Mục tiêu: tăng đều mỗi tháng. | H22: T8/26 FINAL: 1,314 KH
A23: R32 | B23: FB | C23: CLV 12M (FB) — dự báo 12 tháng tới | D23: Dự báo giá trị 1 KH cũ FB đóng góp trong 12 tháng tới, dựa trên AOV và tần suất CỐ ĐỊNH. | E23: AOV_KH_cũ_FB × (365 ÷ 105) ⚠️ freq_FB = 105 ngày — CỐ ĐỊNH từ T8/26, KHÔNG tính động. ⚠️ KHÔNG tính theo cửa sổ 12 tháng rolling. ⚠️ Dùng AOV_KH_cũ_FB (R21), không phải AOV_lần_đầu. | F23: 🟡 metrics_script (công thức cố định) | G23: Tăng khi AOV_KH_cũ tăng. Dùng so sánh vs CAC để đánh giá hiệu quả acquisition. | H23: T8/26 FINAL: 1,725,039đ = 496,244 × 365/105
A24: 📦 DOANH THU & ĐƠN HÀNG — STORE
A25: R35 | B25: Store | C25: DT Store Tổng | D25: Tổng DT 3 cửa hàng (NDC+PH+NGT) sau khi trừ đơn trả. | E25: Σ 'Doanh thu SP sau chiết khấu' của đơn Store trong T, loại ID đơn trả (từ file TRA). ⚠️ fill_daily dùng SCALE = DT_fill / DT_script để bù mismatch do TRA ID ≠ original ID. ⚠️ KHÔNG lấy tổng từ metrics_script. | F25: 🟢 fill_daily.py (cột DT Store = NDC+PH+NGT) | G25: Chỉ số tổng Store. So sánh 3 chi nhánh để tìm điểm yếu. | H25: T8/26 FINAL: 461,185,801đ Target: 730,208,327đ → 63.2%
A26: R36 | B26: Store | C26: ↳ NDC (619 NĐC) | D26: DT riêng chi nhánh Nguyễn Đình Chiểu. | E26: Lọc Store theo Kho = 'NDC', Σ 'Doanh thu SP sau chiết khấu' | F26: 🟢 fill_daily.py | G26: NDC thường ~45–55% DT Store. Nếu tỷ trọng giảm mạnh → kiểm tra vận hành. | H26: T8/26 FINAL: 231,050,152đ (50.1%)
A27: R37 | B27: Store | C27: ↳ Phố Huế (PH) | D27: DT riêng chi nhánh Phố Huế. | E27: Lọc Store theo Kho = 'PH' | F27: 🟢 fill_daily.py | G27: Phố Huế — chi nhánh trung tâm, theo dõi traffic lẻ. | H27: T8/26 FINAL: 122,062,638đ (26.5%)
A28: R38 | B28: Store | C28: ↳ NGT (88 NGT) | D28: DT riêng chi nhánh Nguyễn Gia Trí. | E28: Lọc Store theo Kho = 'NGT' | F28: 🟢 fill_daily.py | G28: NGT — chi nhánh mới nhất, theo dõi tốc độ tăng trưởng. | H28: T8/26 FINAL: 108,073,011đ (23.4%)
A29: R39 | B29: Store | C29: Đơn hàng Store | D29: Số đơn Store giao/bán trong T, đã trừ đơn trả. | E29: COUNT DISTINCT ID đơn Store trong T, loại ID có trong file TRA. ⚠️ ffill cột 'Ngày', 'ID', 'SĐT Khách hàng' trước khi đếm. ⚠️ 1 ID = 1 đơn dù có nhiều dòng sản phẩm. | F29: 🟢 fill_daily.py | G29: Theo dõi traffic bước chân. Đơn tăng mà DT không tăng → AOV đang giảm. | H29: T8/26 FINAL: 1,486 đơn
A30: R40 | B30: Store | C30: AOV Store | D30: Giá trị đơn TB tại Store. | E30: DT Store ÷ Đơn Store | F30: 🟢 Tính từ fill_daily = R35 ÷ R39 | G30: >300K là tốt cho lens walk-in Store. | H30: T8/26 FINAL: 310,354đ
A31: 👤 KHÁCH HÀNG — STORE
A32: R43 | B32: Store | C32: KH mới Store | D32: Số SĐT mua Store trong T chưa từng mua Store trước T_START. | E32: COUNT DISTINCT SĐT đơn Store trong T, SĐT KHÔNG có trong pkl Store với _date < T_START ⚠️ Cột SĐT Store = 'SĐT Khách hàng' (col 12 file Store). ffill trước khi dùng. | F32: 🟡 metrics_script | G32: Mục tiêu: KH mới ≥30% tổng KH Store. | H32: T8/26 FINAL: 511 KH
A33: R44 | B33: Store | C33: AOV lần đầu Store | D33: Chi tiêu TB KH mới Store. | E33: Σ DT đơn KH mới Store trong T ÷ COUNT KH mới Store | F33: 🟡 metrics_script | G33: So sánh với AOV KH cũ Store. Bình thường nên thấp hơn. | H33: T8/26 FINAL: 337,016đ
A34: R45 | B34: Store | C34: Activation Rate Store (Cách B) => Đổi tên thành "Cohort T-3 --> T (Store)" | D34: % KH có first purchase Store trong 90 ngày trước T_START, mua lần 2 trong tháng T, gap ≤ 90 ngày. Giống R17, dùng dữ liệu Store. | E34: R45 — Activation Rate Store — CÁCH B (giống R17, dùng dữ liệu Store) DENOMINATOR: KH có first_ever_purchase Store trong [T_START − 90 ngày, T_START) NUMERATOR: Trong đó, KH nào: (1) mua Store trong tháng T (2) prior_count == 1 (lần mua T là lần 2) (3) gap = ngày mua T − ngày first_ever ≤ 90 ngày ⚠️ Dùng st_hist_ord và st_t_ord thay vì FB ⚠️ Phone Store: str(int(float(p))).lstrip("0") | F34: 🟡 metrics_script (Cách B — 90-day window) | G34: Benchmark ≥5%. Store nên cao hơn hoặc bằng FB do gặp trực tiếp. | H34: T8/26 FINAL: 59/1,834 = 3.22% (Cách B — window 90d trước T_START)
A35: R46 | B35: Store | C35: Cohort T-1→T (Store) | D35: % KH mới Store tháng T-1 có đơn Store trong T. | E35: COUNT(KH mới Store T-1 có đơn Store trong T) ÷ COUNT(KH mới Store T-1) | F35: 🟡 metrics_script | G35: 4–10% là bình thường. >12% = tốt. | H35: T8/26 FINAL: 33/640 = 5.16% (cohort KH mới Store T7)
A36: R48 | B36: Store | C36: KH cũ Store mua lại | D36: Số SĐT có đơn Store trong T VÀ đã có đơn Store trước T_START. | E36: COUNT DISTINCT SĐT đơn Store trong T, SĐT CÓ trong pkl Store với _date < T_START | F36: 🟡 metrics_script | G36: Nguồn DT ổn định Store. Mục tiêu chiếm 55–70% tổng KH Store. | H36: T8/26 FINAL: 768 KH
A37: R49 | B37: Store | C37: AOV KH cũ Store ← dùng tính CLV | D37: Tổng DT KH cũ Store ÷ số KH cũ. ⚠️ Dùng để tính CLV 12M Store và CLV realized Store. | E37: Σ DT đơn KH cũ Store trong T ÷ COUNT KH cũ Store | F37: 🟡 metrics_script | G37: Dùng tính CLV Store. Theo dõi xu hướng — giảm liên tiếp 3 tháng cần điều tra. | H37: T8/26 FINAL: 378,254đ
A38: R50 | B38: Store | C38: % Retention Store | D38: Tỷ lệ KH cũ / tổng KH Store trong T. | E38: KH cũ Store ÷ (KH mới + KH cũ Store) | F38: 🟡 Tính từ R43+R48 | G38: Target: 55–70%. Dưới 50% = Store đang phụ thuộc nhiều vào KH mới. | H38: T8/26 FINAL: 60.05%
A39: R51 | B39: Store | C39: ↳ Mua lại ≤30 ngày (Store) | D39: KH cũ Store trong T có ngày mua cuối ≤30 ngày trước T_START. | E39: COUNT KH cũ Store trong T, (T_START − max(_date trước T)) ≤ 30 | F39: 🟡 metrics_script | G39: Nhóm mua lại sớm nhất — lens 1M hoặc KH trung thành cao. | H39: T8/26 FINAL: 168 KH
A40: R53 | B40: Store | C40: ↳ Mua lại 31–90 ngày (Store) | D40: KH cũ Store trong T có ngày mua cuối 31–90 ngày trước T_START. | E40: COUNT KH cũ Store trong T, 31 ≤ (T_START − max(_date trước T)) ≤ 90 | F40: 🟡 metrics_script | G40: Core lens 1M/3M Store. | H40: T8/26 FINAL: 218 KH
...

Sheet 📊 MASTER
A1: CARASE FB & STORE • BẢNG CHỈ SỐ TỔNG HỢP • T1/2025 → T9/2026
A2: ⬜ Baseline T1/2025–T5/2026 🟡 Upload Nhanh.vn cuối tháng → Claude tính 🟢 Tự kéo từ DAILY T6–T9
A3: Nhóm | B3: Chỉ số | C3: Đơn vị | D3: T1/25 | E3: T2/25 | F3: T3/25 | G3: T4/25 | H3: T5/25 | I3: T6/25 | J3: T7/25 | K3: T8/25 | L3: T9/25 | M3: T10/25 | N3: T11/25 | O3: T12/25 | P3: T1/26 | Q3: T2/26 | R3: T3/26 | S3: T4/26 | T3: T5/26 | U3: T6/26 | V3: T7/26 | W3: T8/26 | X3: T9/26 | Y3: T10/26 | Z3: T11/26 | AA3: T12/26
A4: 1️⃣ FACEBOOK
A5: ── 📦 DOANH THU & ADS ──
B6: Doanh thu FB | C6: đồng | D6: 2593266408 | E6: 1552035250 | F6: 1710878799 | G6: 1625165700 | H6: 1612742619 | I6: 1485108141 | J6: 1516653857 | K6: 1524295202 | L6: 1252820587 | M6: 1404904915 | N6: 1453058083 | O6: 1544416636 | P6: 1734857213 | Q6: 1395864733 | R6: 1253152295 | S6: 1160967589 | T6: 1110861751 | U6: 1108267977 | V6: 1196538826 | W6: 1152990671 | X6: 996482993 | Y6: 630370510
B7: Đơn hàng FB | C7: đơn | D7: 4840 | E7: 2758 | F7: 3136 | G7: 3124 | H7: 3210 | I7: 2988 | J7: 3107 | K7: 3191 | L7: 2792 | M7: 3333 | N7: 3431 | O7: 3486 | P7: 3818 | Q7: 2978 | R7: 2761 | S7: 2540 | T7: 2451 | U7: 2470 | V7: 2822 | W7: 2630 | X7: 2338 | Y7: 1462
B8: AOV FB | C8: đồng/đơn | D8: 535799 | E8: 562739 | F8: 545561 | G8: 520219 | H8: 502412 | I8: 497024 | J8: 488141 | K8: 477686 | L8: 448718 | M8: 421514 | N8: 423509 | O8: 443034 | P8: 454389 | Q8: 468726 | R8: 453876 | S8: 457074 | T8: 453228 | U8: 448691 | V8: 424004 | W8: 438399 | X8: 426212 | Y8: 431170
B9: CMT + Inbox Vpage | C9: lượt | D9: 9627 | E9: 6309 | F9: 6503 | G9: 6784 | H9: 6098 | I9: 5749 | J9: 6827 | K9: 6173 | L9: 5668 | M9: 6361 | N9: 6898 | O9: 7275 | P9: 9054 | Q9: 7364 | R9: 5790 | S9: 4999 | T9: 5231 | U9: 5789 | V9: 5129 | W9: 4841 | X9: 4205 | Y9: 3059
C10: đồng
B11: CR% (Đơn FB / CMT+IB) | C11: % | D11: 0.50275267 | E11: 0.43715327 | F11: 0.48223897 | G11: 0.46049528 | H11: 0.5264021 | I11: 0.51974256 | J11: 0.45510473 | K11: 0.51692856 | L11: 0.49258998 | M11: 0.52397422 | N11: 0.49739055 | O11: 0.47917526 | P11: 0.42169207 | Q11: 0.40439978 | R11: 0.47685665 | S11: 0.50810162 | T11: 0.46855286 | U11: 0.42667127 | V11: 0.55020472 | W11: 0.54327618 | X11: 0.55600476 | Y11: =Y7/Y9 -> 0.47793397
C12: lần
A13: ── 👤 KHÁCH HÀNG FB ──
A14: Acquisition
B15: KH mới FB | C15: KH | D15: 4577 | E15: 2189 | F15: 2155 | G15: 1839 | H15: 1712 | I15: 1497 | J15: 1451 | K15: 1396 | L15: 1181 | M15: 1406 | N15: 1436 | O15: 1351 | P15: 1579 | Q15: 1102 | R15: 988 | S15: 797 | T15: 704 | U15: 706 | V15: 872 | W15: 769 | X15: 713 | Y15: 395
B16: ↳ AOV lần đầu FB | C16: đồng/đơn | D16: 566586 | E16: 612368 | F16: 594273 | G16: 559704 | H16: 536669 | I16: 521893 | J16: 502606 | K16: 506250 | L16: 461143 | M16: 418980 | N16: 428557 | O16: 448014 | P16: 453818 | Q16: 452441 | R16: 468173 | S16: 440712 | T16: 440995 | U16: 447465 | V16: 418543 | W16: 433780 | X16: 416312 | Y16: 410526
B17: Activation: lần 1→2 trong 90 ngày | C17: % | D17: 0 | E17: 343 | F17: 602 | G17: 518 | H17: 418 | I17: 311 | J17: 262 | K17: 205 | L17: 169 | M17: 192 | N17: 185 | O17: 229 | P17: 207 | Q17: 171 | R17: 148 | S17: 128 | T17: 99 | U17: 106 | V17: 119 | W17: 125 | X17: 97 | Y17: 86
B18: Cohort: KH mới T-1 → mua lại T này | C18: % | D18: 0 | E18: 383 | F18: 213 | G18: 182 | H18: 143 | I18: 127 | J18: 107 | K18: 95 | L18: 90 | M18: 97 | N18: 99 | O18: 107 | P18: 105 | Q18: 93 | R18: 59 | S18: 66 | T18: 57 | U18: 58 | V18: 72 | W18: 81 | X18: 48 | Y18: 39
A19: Retention
B20: KH cũ FB mua lại (tổng tháng) | C20: KH | D20: 0 | E20: 383 | F20: 773 | G20: 1051 | H20: 1251 | I20: 1291 | J20: 1414 | K20: 1524 | L20: 1403 | M20: 1623 | N20: 1743 | O20: 1853 | P20: 1972 | Q20: 1728 | R20: 1554 | S20: 1533 | T20: 1556 | U20: 1554 | V20: 1690 | W20: 1633 | X20: 1407 | Y20: 999
B21: ↳ AOV KH cũ FB | C21: đồng/đơn | D21: 0 | E21: 552378 | F21: 556559 | G21: 566955 | H21: 554729 | I21: 545186 | J21: 556841 | K21: 536464 | L21: 504783 | M21: 502661 | N21: 480579 | O21: 506827 | P21: 516369 | Q21: 519256 | R21: 508750 | S21: 528193 | T21: 514397 | U21: 509883 | V21: 492053 | W21: 501784 | X21: 497266 | Y21: 468682
B22: % Retention FB | C22: % | D22: 0 | E22: 0.1489 | F22: 0.264 | G22: 0.3637 | H22: 0.4222 | I22: 0.4631 | J22: 0.4935 | K22: 0.5219 | L22: 0.543 | M22: 0.5358 | N22: 0.5483 | O22: 0.5783 | P22: 0.5553 | Q22: 0.6106 | R22: 0.6113 | S22: 0.6579 | T22: 0.6885 | U22: 0.6876 | V22: 0.6596 | W22: 0.6799 | X22: 0.6637 | Y22: 0.7166
B23: ↳ Mua lại ≤30 ngày | C23: KH | D23: 208 | E23: 120 | F23: 136 | G23: 123 | H23: 116 | I23: 91 | J23: 95 | K23: 108 | L23: 127 | M23: 126 | N23: 204 | O23: 264 | P23: 227 | Q23: 256 | R23: 185 | S23: 203 | T23: 191 | U23: 395 | V23: 458 | W23: 490 | X23: 376 | Y23: 228
B24: ↳ AOV | C24: đồng/đơn | D24: 580443 | E24: 516482 | F24: 520544 | G24: 506154 | H24: 444870 | I24: 544447 | J24: 553412 | K24: 551739 | L24: 502434 | M24: 487008 | N24: 515800 | O24: 515035 | P24: 565363 | Q24: 487576 | R24: 506915 | S24: 579616 | T24: 498816 | U24: 427919 | V24: 410866 | W24: 473743 | X24: 455758 | Y24: 413368
B25: ↳ Mua lại 31–90 ngày | C25: KH | D25: 704 | E25: 459 | F25: 550 | G25: 374 | H25: 412 | I25: 338 | J25: 394 | K25: 393 | L25: 355 | M25: 478 | N25: 593 | O25: 654 | P25: 777 | Q25: 682 | R25: 681 | S25: 650 | T25: 584 | U25: 491 | V25: 520 | W25: 483 | X25: 388 | Y25: 363
B26: ↳ AOV | C26: đồng/đơn | D26: 584820 | E26: 571884 | F26: 580070 | G26: 536181 | H26: 562449 | I26: 499206 | J26: 537405 | K26: 489004 | L26: 479740 | M26: 498779 | N26: 473184 | O26: 496771 | P26: 507713 | Q26: 521206 | R26: 507917 | S26: 512198 | T26: 532485 | U26: 450680 | V26: 472067 | W26: 524029 | X26: 504574 | Y26: 506010
B27: ↳ Mua lại >90 ngày | C27: KH | D27: 697 | E27: 414 | F27: 566 | G27: 615 | H27: 617 | I27: 600 | J27: 635 | K27: 784 | L27: 602 | M27: 766 | N27: 1005 | O27: 962 | P27: 1034 | Q27: 820 | R27: 712 | S27: 700 | T27: 786 | U27: 698 | V27: 761 | W27: 682 | X27: 548 | Y27: 408
B28: ↳ AOV | C28: đồng/đơn | D28: 606306 | E28: 636101 | F28: 593665 | G28: 587223 | H28: 566389 | I28: 543742 | J28: 554666 | K28: 521419 | L28: 510631 | M28: 481273 | N28: 480211 | O28: 506887 | P28: 525092 | Q28: 523625 | R28: 513235 | S28: 514169 | T28: 504044 | U28: 436911 | V28: 476924 | W28: 503197 | X28: 516325 | Y28: 466381
A29: Loyalty
B30: KH FB mua lần 3+ | C30: KH | D30: 0 | E30: 316 | F30: 651 | G30: 896 | H30: 1064 | I30: 1090 | J30: 1245 | K30: 1331 | L30: 1214 | M30: 1388 | N30: 1495 | O30: 1539 | P30: 1600 | Q30: 1419 | R30: 1325 | S30: 1338 | T30: 1327 | U30: 1297 | V30: 1417 | W30: 1330 | X30: 1120 | Y30: 768
B31: ↳ AOV lần 3+ | C31: đồng/đơn | D31: 0 | E31: 576016 | F31: 575471 | G31: 576936 | H31: 571768 | I31: 556704 | J31: 567906 | K31: 543109 | L31: 512685 | M31: 515872 | N31: 492313 | O31: 519797 | P31: 532066 | Q31: 533361 | R31: 522920 | S31: 539741 | T31: 525308 | U31: 523972 | V31: 505674 | W31: 514455 | X31: 522057 | Y31: 487392
B32: CLV 12 tháng rolling (FB) | C32: đồng/KH | D32: 0 | E32: 1920171 | F32: 1934705 | G32: 1970844 | H32: 1928344 | I32: 1895170 | J32: 1935685 | K32: 1864851 | L32: 1754722 | M32: 1747345 | N32: 1670584 | O32: 1761827 | P32: 1794997 | Q32: 1805033 | R32: 1768512 | S32: 1836099 | T32: 1788142 | U32: 1772450 | V32: 1710470 | W32: 1744297 | X32: 1728591 | Y32: 1629228
A33: 2️⃣ STORE
A34: ── 📦 DOANH THU STORE ──
B35: DT Store Tổng (NDC+PH+NGT+350C*) | C35: đồng | D35: 1091554316 | E35: 499607370 | F35: 567264028 | G35: 528594128 | H35: 498208343 | I35: 543406694 | J35: 582713951 | K35: 511779723 | L35: 450985516 | M35: 563065588 | N35: 617168731 | O35: 797994010 | P35: 925450315 | Q35: 971109989 | R35: 549533678 | S35: 582438107 | T35: 504185071 | U35: 511897403 | V35: 532369434 | W35: 479586306 | X35: 451831952 | Y35: 319808874
B36: ↳ NDC (619 Nguyễn Đình Chiểu) | C36: đồng | D36: 540944566 | E36: 268103870 | F36: 290563128 | G36: 254830500 | H36: 256470352 | I36: 260893480 | J36: 301482693 | K36: 261515520 | L36: 234853685 | M36: 292613845 | N36: 315279874 | O36: 425053629 | P36: 498976878 | Q36: 466415524 | R36: 273260815 | S36: 339489341 | T36: 266591829 | U36: 259327182 | V36: 274528089 | W36: 242620655 | X36: 232187993 | Y36: 164300186
B37: ↳ Phố Huế (02 Phố Huế) | C37: đồng | D37: 356945800 | E37: 145126500 | F37: 172657900 | G37: 176377128 | H37: 152411750 | I37: 181624920 | J37: 159269196 | K37: 153183571 | L37: 141817617 | M37: 176059491 | N37: 178778384 | O37: 210046402 | P37: 212730879 | Q37: 299922606 | R37: 150994415 | S37: 119328315 | T37: 125042886 | U37: 126589058 | V37: 129418093 | W37: 125115639 | X37: 120531728 | Y37: 92240126
B38: ↳ NGT (88 Nguyễn Gia Trí) | C38: đồng | D38: 191584950 | E38: 86377000 | F38: 103913000 | G38: 97386500 | H38: 89326241 | I38: 100888294 | J38: 121962062 | K38: 96405115 | L38: 74134714 | M38: 94392252 | N38: 123110473 | O38: 162893979 | P38: 213742558 | Q38: 204771859 | R38: 125278448 | S38: 123620451 | T38: 112550356 | U38: 125981163 | V38: 128423252 | W38: 111850012 | X38: 99112231 | Y38: 63268562
B39: Đơn hàng Store | C39: đơn | D39: 2635 | E39: 1242 | F39: 1571 | G39: 1512 | H39: 1566 | I39: 1602 | J39: 1752 | K39: 1643 | L39: 1510 | M39: 2061 | N39: 2296 | O39: 2690 | P39: 3020 | Q39: 2950 | R39: 1851 | S39: 1843 | T39: 1718 | U39: 1672 | V39: 1725 | W39: 1542 | X39: 1405 | Y39: 1073
B40: AOV Store | C40: đồng/đơn | D40: 414252 | E40: 402260 | F40: 361085 | G40: 349599 | H40: 318141 | I40: 339205 | J40: 332599 | K40: 311491 | L40: 298666 | M40: 273200 | N40: 268802 | O40: 296652 | P40: 306441 | Q40: 329190 | R40: 296885 | S40: 316027 | T40: 293472 | U40: 306159 | V40: 308620 | W40: 311016 | X40: 321589 | Y40: 298051
...

Sheet 📅 DAILY T9-25
A1: DAILY INPUT • THÁNG 9/2025 • CARASE FB & STORE
A2: 🟡 Ô VÀNG = Team điền mỗi ngày | 🟢 Ô XANH = Tự tính | Deadline 22:00
A3: 📅 THỜI GIAN | C3: 📱 FACEBOOK | E3: 📢 ADS | G3: 🏪 STORE | K3: 👓 O3 | L3: 📝 | M3: 📊 AUTO | O3: 📊 AUTO | Q3: 📊
A4: Ngày | B4: T | C4: DT FB (đ) | D4: Đơn FB | E4: CMT+IB (Vpage) | F4: CP Ads (đ) | G4: DT NDC (đ) | H4: DT PH (đ) | I4: DT NGT (đ) | J4: Đơn Store | K4: DT O3 (đ) | L4: Ghi chú | M4: DT Store (=G+H+I) | N4: DT Total (=FB+Store) | O4: AOV FB (C/D) | P4: AOV Store (M/J) | Q4: CR% (D/E)
A5: TARGET/THÁNG
A6: 45901 | B6: T2 | C6: 19591791 | D6: 49 | G6: 4758280 | H6: 2213852 | J6: 26 | M6: =IF(SUM(G6:I6)>0,SUM(G6:I6),"") -> 6972132 | N6: =IF(N(C6)+N(M6)>0,N(C6)+N(M6),"") -> 26563923 | O6: =IFERROR(IF(D6>0,C6/D6,""),"") -> 399832.47 | P6: =IFERROR(IF(J6>0,M6/J6,""),"") -> 268158.92 | Q6: =IFERROR(IF(E6>0,D6/E6,""),"")
A7: 45902 | B7: T3 | C7: 14043038 | D7: 35 | G7: 5022454 | H7: 5236003 | J7: 33 | K7: 416666 | M7: =IF(SUM(G7:I7)>0,SUM(G7:I7),"") -> 10258457 | N7: =IF(N(C7)+N(M7)>0,N(C7)+N(M7),"") -> 24301495 | O7: =IFERROR(IF(D7>0,C7/D7,""),"") -> 401229.66 | P7: =IFERROR(IF(J7>0,M7/J7,""),"") -> 310862.33 | Q7: =IFERROR(IF(E7>0,D7/E7,""),"")
A8: 45903 | B8: T4 | C8: 31595138 | D8: 64 | G8: 5662486 | I8: 2961658 | J8: 31 | K8: 4030000 | M8: =IF(SUM(G8:I8)>0,SUM(G8:I8),"") -> 8624144 | N8: =IF(N(C8)+N(M8)>0,N(C8)+N(M8),"") -> 40219282 | O8: =IFERROR(IF(D8>0,C8/D8,""),"") -> 493674.03 | P8: =IFERROR(IF(J8>0,M8/J8,""),"") -> 278198.19 | Q8: =IFERROR(IF(E8>0,D8/E8,""),"")
A9: 45904 | B9: T5 | C9: 36834727 | D9: 81 | G9: 12685411 | H9: 11268018 | I9: 3229141 | J9: 83 | M9: =IF(SUM(G9:I9)>0,SUM(G9:I9),"") -> 27182570 | N9: =IF(N(C9)+N(M9)>0,N(C9)+N(M9),"") -> 64017297 | O9: =IFERROR(IF(D9>0,C9/D9,""),"") -> 454749.72 | P9: =IFERROR(IF(J9>0,M9/J9,""),"") -> 327500.84 | Q9: =IFERROR(IF(E9>0,D9/E9,""),"")
A10: 45905 | B10: T6 | C10: 58478953 | D10: 115 | G10: 7231104 | H10: 3876508 | I10: 2258894 | J10: 60 | K10: 5809149 | M10: =IF(SUM(G10:I10)>0,SUM(G10:I10),"") -> 13366506 | N10: =IF(N(C10)+N(M10)>0,N(C10)+N(M10),"") -> 71845459 | O10: =IFERROR(IF(D10>0,C10/D10,""),"") -> 508512.63 | P10: =IFERROR(IF(J10>0,M10/J10,""),"") -> 222775.1 | Q10: =IFERROR(IF(E10>0,D10/E10,""),"")
A11: 45906 | B11: T7 | C11: 58385506 | D11: 119 | G11: 8169929 | H11: 4431012 | I11: 3696805 | J11: 55 | K11: 444444 | M11: =IF(SUM(G11:I11)>0,SUM(G11:I11),"") -> 16297746 | N11: =IF(N(C11)+N(M11)>0,N(C11)+N(M11),"") -> 74683252 | O11: =IFERROR(IF(D11>0,C11/D11,""),"") -> 490634.5 | P11: =IFERROR(IF(J11>0,M11/J11,""),"") -> 296322.65 | Q11: =IFERROR(IF(E11>0,D11/E11,""),"")
A12: 45907 | B12: CN | C12: 39395437 | D12: 96 | G12: 7235327 | H12: 5821019 | I12: 3292484 | J12: 52 | K12: 83333 | M12: =IF(SUM(G12:I12)>0,SUM(G12:I12),"") -> 16348830 | N12: =IF(N(C12)+N(M12)>0,N(C12)+N(M12),"") -> 55744267 | O12: =IFERROR(IF(D12>0,C12/D12,""),"") -> 410369.14 | P12: =IFERROR(IF(J12>0,M12/J12,""),"") -> 314400.58 | Q12: =IFERROR(IF(E12>0,D12/E12,""),"")
A13: 45908 | B13: T2 | C13: 38961107 | D13: 83 | G13: 5970868 | H13: 3200010 | I13: 3458029 | J13: 40 | K13: 1130158 | M13: =IF(SUM(G13:I13)>0,SUM(G13:I13),"") -> 12628907 | N13: =IF(N(C13)+N(M13)>0,N(C13)+N(M13),"") -> 51590014 | O13: =IFERROR(IF(D13>0,C13/D13,""),"") -> 469410.93 | P13: =IFERROR(IF(J13>0,M13/J13,""),"") -> 315722.67 | Q13: =IFERROR(IF(E13>0,D13/E13,""),"")
A14: 45909 | B14: T3 | C14: 47980110 | D14: 97 | G14: 4494547 | H14: 5326522 | I14: 1101999 | J14: 39 | K14: 761659 | M14: =IF(SUM(G14:I14)>0,SUM(G14:I14),"") -> 10923068 | N14: =IF(N(C14)+N(M14)>0,N(C14)+N(M14),"") -> 58903178 | O14: =IFERROR(IF(D14>0,C14/D14,""),"") -> 494640.31 | P14: =IFERROR(IF(J14>0,M14/J14,""),"") -> 280078.67 | Q14: =IFERROR(IF(E14>0,D14/E14,""),"")
A15: 45910 | B15: T4 | C15: 42957529 | D15: 89 | G15: 7731000 | H15: 3933022 | I15: 1216394 | J15: 41 | K15: 1507200 | M15: =IF(SUM(G15:I15)>0,SUM(G15:I15),"") -> 12880416 | N15: =IF(N(C15)+N(M15)>0,N(C15)+N(M15),"") -> 55837945 | O15: =IFERROR(IF(D15>0,C15/D15,""),"") -> 482668.87 | P15: =IFERROR(IF(J15>0,M15/J15,""),"") -> 314156.49 | Q15: =IFERROR(IF(E15>0,D15/E15,""),"")
A16: 45911 | B16: T5 | C16: 35423290 | D16: 82 | G16: 6536399 | H16: 4443509 | I16: 1614151 | J16: 38 | M16: =IF(SUM(G16:I16)>0,SUM(G16:I16),"") -> 12594059 | N16: =IF(N(C16)+N(M16)>0,N(C16)+N(M16),"") -> 48017349 | O16: =IFERROR(IF(D16>0,C16/D16,""),"") -> 431991.34 | P16: =IFERROR(IF(J16>0,M16/J16,""),"") -> 331422.61 | Q16: =IFERROR(IF(E16>0,D16/E16,""),"")
A17: 45912 | B17: T6 | C17: 41835540 | D17: 106 | G17: 8229871 | H17: 6027008 | I17: 1746928 | J17: 57 | K17: 296296 | M17: =IF(SUM(G17:I17)>0,SUM(G17:I17),"") -> 16003807 | N17: =IF(N(C17)+N(M17)>0,N(C17)+N(M17),"") -> 57839347 | O17: =IFERROR(IF(D17>0,C17/D17,""),"") -> 394674.91 | P17: =IFERROR(IF(J17>0,M17/J17,""),"") -> 280768.54 | Q17: =IFERROR(IF(E17>0,D17/E17,""),"")
A18: 45913 | B18: T7 | C18: 39390229 | D18: 94 | G18: 9591424 | H18: 4290009 | I18: 2593449 | J18: 59 | M18: =IF(SUM(G18:I18)>0,SUM(G18:I18),"") -> 16474882 | N18: =IF(N(C18)+N(M18)>0,N(C18)+N(M18),"") -> 55865111 | O18: =IFERROR(IF(D18>0,C18/D18,""),"") -> 419044.99 | P18: =IFERROR(IF(J18>0,M18/J18,""),"") -> 279235.29 | Q18: =IFERROR(IF(E18>0,D18/E18,""),"")
A19: 45914 | B19: CN | C19: 41538532 | D19: 96 | G19: 10329055 | H19: 7984017 | I19: 2876941 | J19: 70 | K19: 1285700 | M19: =IF(SUM(G19:I19)>0,SUM(G19:I19),"") -> 21190013 | N19: =IF(N(C19)+N(M19)>0,N(C19)+N(M19),"") -> 62728545 | O19: =IFERROR(IF(D19>0,C19/D19,""),"") -> 432693.04 | P19: =IFERROR(IF(J19>0,M19/J19,""),"") -> 302714.47 | Q19: =IFERROR(IF(E19>0,D19/E19,""),"")
A20: 45915 | B20: T2 | C20: 46874211 | D20: 116 | G20: 12566191 | H20: 5017015 | I20: 3173440 | J20: 58 | K20: 324000 | M20: =IF(SUM(G20:I20)>0,SUM(G20:I20),"") -> 20756646 | N20: =IF(N(C20)+N(M20)>0,N(C20)+N(M20),"") -> 67630857 | O20: =IFERROR(IF(D20>0,C20/D20,""),"") -> 404088.03 | P20: =IFERROR(IF(J20>0,M20/J20,""),"") -> 357873.21 | Q20: =IFERROR(IF(E20>0,D20/E20,""),"")
A21: 45916 | B21: T3 | C21: 49914494 | D21: 104 | G21: 7255113 | H21: 4552009 | I21: 1835984 | J21: 43 | K21: 5024001 | M21: =IF(SUM(G21:I21)>0,SUM(G21:I21),"") -> 13643106 | N21: =IF(N(C21)+N(M21)>0,N(C21)+N(M21),"") -> 63557600 | O21: =IFERROR(IF(D21>0,C21/D21,""),"") -> 479947.06 | P21: =IFERROR(IF(J21>0,M21/J21,""),"") -> 317281.53 | Q21: =IFERROR(IF(E21>0,D21/E21,""),"")
A22: 45917 | B22: T4 | C22: 54567632 | D22: 102 | G22: 5825722 | H22: 9666637 | I22: 2183482 | J22: 35 | K22: 1038000 | M22: =IF(SUM(G22:I22)>0,SUM(G22:I22),"") -> 17675841 | N22: =IF(N(C22)+N(M22)>0,N(C22)+N(M22),"") -> 72243473 | O22: =IFERROR(IF(D22>0,C22/D22,""),"") -> 534976.78 | P22: =IFERROR(IF(J22>0,M22/J22,""),"") -> 505024.03 | Q22: =IFERROR(IF(E22>0,D22/E22,""),"")
A23: 45918 | B23: T5 | C23: 39077968 | D23: 87 | G23: 5222939 | H23: 5923243 | I23: 664984 | J23: 39 | K23: 1673809 | M23: =IF(SUM(G23:I23)>0,SUM(G23:I23),"") -> 11811166 | N23: =IF(N(C23)+N(M23)>0,N(C23)+N(M23),"") -> 50889134 | O23: =IFERROR(IF(D23>0,C23/D23,""),"") -> 449172.05 | P23: =IFERROR(IF(J23>0,M23/J23,""),"") -> 302850.41 | Q23: =IFERROR(IF(E23>0,D23/E23,""),"")
A24: 45919 | B24: T6 | C24: 48614994 | D24: 113 | G24: 7338093 | H24: 5774032 | I24: 2459929 | J24: 63 | M24: =IF(SUM(G24:I24)>0,SUM(G24:I24),"") -> 15572054 | N24: =IF(N(C24)+N(M24)>0,N(C24)+N(M24),"") -> 64187048 | O24: =IFERROR(IF(D24>0,C24/D24,""),"") -> 430221.19 | P24: =IFERROR(IF(J24>0,M24/J24,""),"") -> 247175.46 | Q24: =IFERROR(IF(E24>0,D24/E24,""),"")
A25: 45920 | B25: T7 | C25: 64184051 | D25: 133 | G25: 11842915 | H25: 3043003 | I25: 2584176 | J25: 60 | M25: =IF(SUM(G25:I25)>0,SUM(G25:I25),"") -> 17470094 | N25: =IF(N(C25)+N(M25)>0,N(C25)+N(M25),"") -> 81654145 | O25: =IFERROR(IF(D25>0,C25/D25,""),"") -> 482586.85 | P25: =IFERROR(IF(J25>0,M25/J25,""),"") -> 291168.23 | Q25: =IFERROR(IF(E25>0,D25/E25,""),"")
A26: 45921 | B26: CN | C26: 29669073 | D26: 69 | G26: 11213258 | H26: 5978018 | I26: 6314664 | J26: 76 | K26: 2301376 | M26: =IF(SUM(G26:I26)>0,SUM(G26:I26),"") -> 23505940 | N26: =IF(N(C26)+N(M26)>0,N(C26)+N(M26),"") -> 53175013 | O26: =IFERROR(IF(D26>0,C26/D26,""),"") -> 429986.57 | P26: =IFERROR(IF(J26>0,M26/J26,""),"") -> 309288.68 | Q26: =IFERROR(IF(E26>0,D26/E26,""),"")
A27: 45922 | B27: T2 | C27: 33268229 | D27: 73 | G27: 4242893 | H27: 4755512 | I27: 2546967 | J27: 42 | K27: 1790066 | M27: =IF(SUM(G27:I27)>0,SUM(G27:I27),"") -> 11545372 | N27: =IF(N(C27)+N(M27)>0,N(C27)+N(M27),"") -> 44813601 | O27: =IFERROR(IF(D27>0,C27/D27,""),"") -> 455729.16 | P27: =IFERROR(IF(J27>0,M27/J27,""),"") -> 274889.81 | Q27: =IFERROR(IF(E27>0,D27/E27,""),"")
A28: 45923 | B28: T3 | C28: 57928241 | D28: 130 | G28: 7881467 | H28: 3430847 | I28: 2316945 | J28: 41 | K28: 3048770 | M28: =IF(SUM(G28:I28)>0,SUM(G28:I28),"") -> 13629259 | N28: =IF(N(C28)+N(M28)>0,N(C28)+N(M28),"") -> 71557500 | O28: =IFERROR(IF(D28>0,C28/D28,""),"") -> 445601.85 | P28: =IFERROR(IF(J28>0,M28/J28,""),"") -> 332420.95 | Q28: =IFERROR(IF(E28>0,D28/E28,""),"")
A29: 45924 | B29: T4 | C29: 49006759 | D29: 109 | G29: 8641766 | H29: 3799845 | I29: 3535932 | J29: 62 | K29: 2779974 | M29: =IF(SUM(G29:I29)>0,SUM(G29:I29),"") -> 15977543 | N29: =IF(N(C29)+N(M29)>0,N(C29)+N(M29),"") -> 64984302 | O29: =IFERROR(IF(D29>0,C29/D29,""),"") -> 449603.29 | P29: =IFERROR(IF(J29>0,M29/J29,""),"") -> 257702.31 | Q29: =IFERROR(IF(E29>0,D29/E29,""),"")
A30: 45925 | B30: T5 | C30: 43995205 | D30: 102 | G30: 8357707 | H30: 3545005 | I30: 3694207 | J30: 53 | M30: =IF(SUM(G30:I30)>0,SUM(G30:I30),"") -> 15596919 | N30: =IF(N(C30)+N(M30)>0,N(C30)+N(M30),"") -> 59592124 | O30: =IFERROR(IF(D30>0,C30/D30,""),"") -> 431325.54 | P30: =IFERROR(IF(J30>0,M30/J30,""),"") -> 294281.49 | Q30: =IFERROR(IF(E30>0,D30/E30,""),"")
A31: 45926 | B31: T6 | C31: 46995217 | D31: 112 | G31: 6275861 | H31: 5301898 | I31: 2341943 | J31: 51 | K31: 1286000 | M31: =IF(SUM(G31:I31)>0,SUM(G31:I31),"") -> 13919702 | N31: =IF(N(C31)+N(M31)>0,N(C31)+N(M31),"") -> 60914919 | O31: =IFERROR(IF(D31>0,C31/D31,""),"") -> 419600.15 | P31: =IFERROR(IF(J31>0,M31/J31,""),"") -> 272935.33 | Q31: =IFERROR(IF(E31>0,D31/E31,""),"")
A32: 45927 | B32: T7 | C32: 49614957 | D32: 115 | G32: 10291567 | H32: 6519027 | I32: 1619345 | J32: 69 | M32: =IF(SUM(G32:I32)>0,SUM(G32:I32),"") -> 18429939 | N32: =IF(N(C32)+N(M32)>0,N(C32)+N(M32),"") -> 68044896 | O32: =IFERROR(IF(D32>0,C32/D32,""),"") -> 431434.41 | P32: =IFERROR(IF(J32>0,M32/J32,""),"") -> 267100.57 | Q32: =IFERROR(IF(E32>0,D32/E32,""),"")
A33: 45928 | B33: CN | C33: 29293212 | D33: 80 | G33: 9007927 | H33: 4189014 | I33: 4283960 | J33: 56 | M33: =IF(SUM(G33:I33)>0,SUM(G33:I33),"") -> 17480901 | N33: =IF(N(C33)+N(M33)>0,N(C33)+N(M33),"") -> 46774113 | O33: =IFERROR(IF(D33>0,C33/D33,""),"") -> 366165.15 | P33: =IFERROR(IF(J33>0,M33/J33,""),"") -> 312158.95 | Q33: =IFERROR(IF(E33>0,D33/E33,""),"")
A34: 45929 | B34: T2 | C34: 36826801 | D34: 80 | G34: 5650575 | H34: 1750002 | I34: 1260956 | J34: 33 | K34: 3187081 | M34: =IF(SUM(G34:I34)>0,SUM(G34:I34),"") -> 8661533 | N34: =IF(N(C34)+N(M34)>0,N(C34)+N(M34),"") -> 45488334 | O34: =IFERROR(IF(D34>0,C34/D34,""),"") -> 460335.01 | P34: =IFERROR(IF(J34>0,M34/J34,""),"") -> 262470.7 | Q34: =IFERROR(IF(E34>0,D34/E34,""),"")
A35: 45930 | B35: T3 | C35: 26578616 | D35: 66 | G35: 9591536 | H35: 522001 | I35: 3270927 | J35: 44 | K35: 2843714 | M35: =IF(SUM(G35:I35)>0,SUM(G35:I35),"") -> 13384464 | N35: =IF(N(C35)+N(M35)>0,N(C35)+N(M35),"") -> 39963080 | O35: =IFERROR(IF(D35>0,C35/D35,""),"") -> 402706.3 | P35: =IFERROR(IF(J35>0,M35/J35,""),"") -> 304192.36 | Q35: =IFERROR(IF(E35>0,D35/E35,""),"")

Sheet 📅 DAILY T10-25
A1: DAILY INPUT • THÁNG 10/2025 • CARASE FB & STORE
A2: 🟡 Ô VÀNG = Team điền mỗi ngày | 🟢 Ô XANH = Tự tính | Deadline 22:00
A3: 📅 THỜI GIAN | C3: 📱 FACEBOOK | E3: 📢 ADS | G3: 🏪 STORE | K3: 👓 O3 | L3: 📝 | M3: 📊 AUTO | O3: 📊 AUTO | Q3: 📊
A4: Ngày | B4: T | C4: DT FB (đ) | D4: Đơn FB | E4: CMT+IB (Vpage) | F4: CP Ads (đ) | G4: DT NDC (đ) | H4: DT PH (đ) | I4: DT NGT (đ) | J4: Đơn Store | K4: DT O3 (đ) | L4: Ghi chú | M4: DT Store (=G+H+I) | N4: DT Total (=FB+Store) | O4: AOV FB (C/D) | P4: AOV Store (M/J) | Q4: CR% (D/E)
A5: TARGET/THÁNG
A6: 45931 | B6: T4 | C6: 45010927 | D6: 88 | G6: 8633814 | H6: 7409030 | I6: 3053185 | J6: 56 | K6: 4639334 | M6: =IF(SUM(G6:I6)>0,SUM(G6:I6),"") -> 19096029 | N6: =IF(N(C6)+N(M6)>0,N(C6)+N(M6),"") -> 64106956 | O6: =IFERROR(IF(D6>0,C6/D6,""),"") -> 511487.81 | P6: =IFERROR(IF(J6>0,M6/J6,""),"") -> 341000.52 | Q6: =IFERROR(IF(E6>0,D6/E6,""),"")
A7: 45932 | B7: T5 | C7: 58008442 | D7: 140 | G7: 17493440 | H7: 5845048 | I7: 2381135 | J7: 71 | K7: 231481 | M7: =IF(SUM(G7:I7)>0,SUM(G7:I7),"") -> 25719623 | N7: =IF(N(C7)+N(M7)>0,N(C7)+N(M7),"") -> 83728065 | O7: =IFERROR(IF(D7>0,C7/D7,""),"") -> 414346.01 | P7: =IFERROR(IF(J7>0,M7/J7,""),"") -> 362248.21 | Q7: =IFERROR(IF(E7>0,D7/E7,""),"")
A8: 45933 | B8: T6 | C8: 49601544 | D8: 115 | G8: 8370298 | H8: 5441235 | I8: 2403172 | J8: 75 | K8: 2990725 | M8: =IF(SUM(G8:I8)>0,SUM(G8:I8),"") -> 16214705 | N8: =IF(N(C8)+N(M8)>0,N(C8)+N(M8),"") -> 65816249 | O8: =IFERROR(IF(D8>0,C8/D8,""),"") -> 431317.77 | P8: =IFERROR(IF(J8>0,M8/J8,""),"") -> 216196.07 | Q8: =IFERROR(IF(E8>0,D8/E8,""),"")
A9: 45934 | B9: T7 | C9: 61264067 | D9: 144 | G9: 10959619 | H9: 8020160 | I9: 5712537 | J9: 90 | K9: 259259 | M9: =IF(SUM(G9:I9)>0,SUM(G9:I9),"") -> 24692316 | N9: =IF(N(C9)+N(M9)>0,N(C9)+N(M9),"") -> 85956383 | O9: =IFERROR(IF(D9>0,C9/D9,""),"") -> 425444.91 | P9: =IFERROR(IF(J9>0,M9/J9,""),"") -> 274359.07 | Q9: =IFERROR(IF(E9>0,D9/E9,""),"")
A10: 45935 | B10: CN | C10: 45157076 | D10: 94 | G10: 11523563 | H10: 4457011 | I10: 3321838 | J10: 72 | M10: =IF(SUM(G10:I10)>0,SUM(G10:I10),"") -> 19302412 | N10: =IF(N(C10)+N(M10)>0,N(C10)+N(M10),"") -> 64459488 | O10: =IFERROR(IF(D10>0,C10/D10,""),"") -> 480394.43 | P10: =IFERROR(IF(J10>0,M10/J10,""),"") -> 268089.06 | Q10: =IFERROR(IF(E10>0,D10/E10,""),"")
A11: 45936 | B11: T2 | C11: 51694731 | D11: 118 | G11: 4617677 | H11: 3110004 | I11: 1429954 | J11: 37 | K11: 3377158 | M11: =IF(SUM(G11:I11)>0,SUM(G11:I11),"") -> 9157635 | N11: =IF(N(C11)+N(M11)>0,N(C11)+N(M11),"") -> 60852366 | O11: =IFERROR(IF(D11>0,C11/D11,""),"") -> 438090.94 | P11: =IFERROR(IF(J11>0,M11/J11,""),"") -> 247503.65 | Q11: =IFERROR(IF(E11>0,D11/E11,""),"")
A12: 45937 | B12: T3 | C12: 39795110 | D12: 80 | G12: 11169060 | H12: 2084014 | I12: 4552574 | J12: 66 | K12: 648148 | M12: =IF(SUM(G12:I12)>0,SUM(G12:I12),"") -> 17805648 | N12: =IF(N(C12)+N(M12)>0,N(C12)+N(M12),"") -> 57600758 | O12: =IFERROR(IF(D12>0,C12/D12,""),"") -> 497438.88 | P12: =IFERROR(IF(J12>0,M12/J12,""),"") -> 269782.55 | Q12: =IFERROR(IF(E12>0,D12/E12,""),"")
A13: 45938 | B13: T4 | C13: 45887750 | D13: 113 | G13: 5852671 | H13: 7328017 | I13: 1549194 | J13: 50 | K13: 762117 | M13: =IF(SUM(G13:I13)>0,SUM(G13:I13),"") -> 14729882 | N13: =IF(N(C13)+N(M13)>0,N(C13)+N(M13),"") -> 60617632 | O13: =IFERROR(IF(D13>0,C13/D13,""),"") -> 406086.28 | P13: =IFERROR(IF(J13>0,M13/J13,""),"") -> 294597.64 | Q13: =IFERROR(IF(E13>0,D13/E13,""),"")
A14: 45939 | B14: T5 | C14: 46210499 | D14: 122 | G14: 11618778 | H14: 4602012 | I14: 3268913 | J14: 73 | K14: 1119295 | M14: =IF(SUM(G14:I14)>0,SUM(G14:I14),"") -> 19489703 | N14: =IF(N(C14)+N(M14)>0,N(C14)+N(M14),"") -> 65700202 | O14: =IFERROR(IF(D14>0,C14/D14,""),"") -> 378774.58 | P14: =IFERROR(IF(J14>0,M14/J14,""),"") -> 266982.23 | Q14: =IFERROR(IF(E14>0,D14/E14,""),"")
A15: 45940 | B15: T6 | C15: 63115431 | D15: 151 | G15: 9994773 | H15: 6855007 | I15: 2338358 | J15: 86 | K15: 7349175 | M15: =IF(SUM(G15:I15)>0,SUM(G15:I15),"") -> 19188138 | N15: =IF(N(C15)+N(M15)>0,N(C15)+N(M15),"") -> 82303569 | O15: =IFERROR(IF(D15>0,C15/D15,""),"") -> 417982.99 | P15: =IFERROR(IF(J15>0,M15/J15,""),"") -> 223117.88 | Q15: =IFERROR(IF(E15>0,D15/E15,""),"")
A16: 45941 | B16: T7 | C16: 43361508 | D16: 95 | G16: 14862245 | H16: 8419609 | I16: 2925329 | J16: 103 | K16: 868800 | M16: =IF(SUM(G16:I16)>0,SUM(G16:I16),"") -> 26207183 | N16: =IF(N(C16)+N(M16)>0,N(C16)+N(M16),"") -> 69568691 | O16: =IFERROR(IF(D16>0,C16/D16,""),"") -> 456436.93 | P16: =IFERROR(IF(J16>0,M16/J16,""),"") -> 254438.67 | Q16: =IFERROR(IF(E16>0,D16/E16,""),"")
A17: 45942 | B17: CN | C17: 38404085 | D17: 98 | G17: 10787852 | H17: 8777029 | I17: 5361360 | J17: 90 | K17: 1007407 | M17: =IF(SUM(G17:I17)>0,SUM(G17:I17),"") -> 24926241 | N17: =IF(N(C17)+N(M17)>0,N(C17)+N(M17),"") -> 63330326 | O17: =IFERROR(IF(D17>0,C17/D17,""),"") -> 391878.42 | P17: =IFERROR(IF(J17>0,M17/J17,""),"") -> 276958.23 | Q17: =IFERROR(IF(E17>0,D17/E17,""),"")
A18: 45943 | B18: T2 | C18: 30501930 | D18: 78 | G18: 3761961 | H18: 2757010 | I18: 1915863 | J18: 41 | K18: 1012859 | M18: =IF(SUM(G18:I18)>0,SUM(G18:I18),"") -> 8434834 | N18: =IF(N(C18)+N(M18)>0,N(C18)+N(M18),"") -> 38936764 | O18: =IFERROR(IF(D18>0,C18/D18,""),"") -> 391050.38 | P18: =IFERROR(IF(J18>0,M18/J18,""),"") -> 205727.66 | Q18: =IFERROR(IF(E18>0,D18/E18,""),"")
A19: 45944 | B19: T3 | C19: 47037132 | D19: 123 | G19: 7133409 | H19: 2047008 | I19: 2730829 | J19: 41 | K19: 1820646 | M19: =IF(SUM(G19:I19)>0,SUM(G19:I19),"") -> 11911246 | N19: =IF(N(C19)+N(M19)>0,N(C19)+N(M19),"") -> 58948378 | O19: =IFERROR(IF(D19>0,C19/D19,""),"") -> 382415.71 | P19: =IFERROR(IF(J19>0,M19/J19,""),"") -> 290518.2 | Q19: =IFERROR(IF(E19>0,D19/E19,""),"")
A20: 45945 | B20: T4 | C20: 55649153 | D20: 135 | G20: 9567799 | H20: 6190018 | I20: 2432192 | J20: 61 | K20: 1064814 | M20: =IF(SUM(G20:I20)>0,SUM(G20:I20),"") -> 18190009 | N20: =IF(N(C20)+N(M20)>0,N(C20)+N(M20),"") -> 73839162 | O20: =IFERROR(IF(D20>0,C20/D20,""),"") -> 412215.95 | P20: =IFERROR(IF(J20>0,M20/J20,""),"") -> 298196.87 | Q20: =IFERROR(IF(E20>0,D20/E20,""),"")
A21: 45946 | B21: T5 | C21: 50156379 | D21: 129 | G21: 10855316 | H21: 7121017 | I21: 3567138 | J21: 76 | K21: 509259 | M21: =IF(SUM(G21:I21)>0,SUM(G21:I21),"") -> 21543471 | N21: =IF(N(C21)+N(M21)>0,N(C21)+N(M21),"") -> 71699850 | O21: =IFERROR(IF(D21>0,C21/D21,""),"") -> 388809.14 | P21: =IFERROR(IF(J21>0,M21/J21,""),"") -> 283466.72 | Q21: =IFERROR(IF(E21>0,D21/E21,""),"")
A22: 45947 | B22: T6 | C22: 39413081 | D22: 103 | G22: 5789883 | H22: 7305022 | I22: 5099994 | J22: 74 | K22: 2728304 | M22: =IF(SUM(G22:I22)>0,SUM(G22:I22),"") -> 18194899 | N22: =IF(N(C22)+N(M22)>0,N(C22)+N(M22),"") -> 57607980 | O22: =IFERROR(IF(D22>0,C22/D22,""),"") -> 382651.27 | P22: =IFERROR(IF(J22>0,M22/J22,""),"") -> 245877.01 | Q22: =IFERROR(IF(E22>0,D22/E22,""),"")
A23: 45948 | B23: T7 | C23: 46272506 | D23: 112 | G23: 13734819 | H23: 7032017 | I23: 3290837 | J23: 89 | M23: =IF(SUM(G23:I23)>0,SUM(G23:I23),"") -> 24057673 | N23: =IF(N(C23)+N(M23)>0,N(C23)+N(M23),"") -> 70330179 | O23: =IFERROR(IF(D23>0,C23/D23,""),"") -> 413147.38 | P23: =IFERROR(IF(J23>0,M23/J23,""),"") -> 270310.93 | Q23: =IFERROR(IF(E23>0,D23/E23,""),"")
A24: 45949 | B24: CN | C24: 34450984 | D24: 93 | G24: 5545576 | H24: 4479018 | I24: 4556150 | J24: 58 | K24: 324074 | M24: =IF(SUM(G24:I24)>0,SUM(G24:I24),"") -> 14580744 | N24: =IF(N(C24)+N(M24)>0,N(C24)+N(M24),"") -> 49031728 | O24: =IFERROR(IF(D24>0,C24/D24,""),"") -> 370440.69 | P24: =IFERROR(IF(J24>0,M24/J24,""),"") -> 251392.14 | Q24: =IFERROR(IF(E24>0,D24/E24,""),"")
A25: 45950 | B25: T2 | C25: 38832798 | D25: 93 | G25: 8825547 | H25: 1832002 | I25: 2457713 | J25: 45 | K25: 185185 | M25: =IF(SUM(G25:I25)>0,SUM(G25:I25),"") -> 13115262 | N25: =IF(N(C25)+N(M25)>0,N(C25)+N(M25),"") -> 51948060 | O25: =IFERROR(IF(D25>0,C25/D25,""),"") -> 417556.97 | P25: =IFERROR(IF(J25>0,M25/J25,""),"") -> 291450.27 | Q25: =IFERROR(IF(E25>0,D25/E25,""),"")
A26: 45951 | B26: T3 | C26: 44302785 | D26: 110 | G26: 12161723 | H26: 3232005 | I26: 2261693 | J26: 55 | M26: =IF(SUM(G26:I26)>0,SUM(G26:I26),"") -> 17655421 | N26: =IF(N(C26)+N(M26)>0,N(C26)+N(M26),"") -> 61958206 | O26: =IFERROR(IF(D26>0,C26/D26,""),"") -> 402752.59 | P26: =IFERROR(IF(J26>0,M26/J26,""),"") -> 321007.65 | Q26: =IFERROR(IF(E26>0,D26/E26,""),"")
A27: 45952 | B27: T4 | C27: 41505430 | D27: 96 | G27: 10594670 | H27: 6844015 | I27: 3053957 | J27: 65 | K27: 2720000 | M27: =IF(SUM(G27:I27)>0,SUM(G27:I27),"") -> 20492642 | N27: =IF(N(C27)+N(M27)>0,N(C27)+N(M27),"") -> 61998072 | O27: =IFERROR(IF(D27>0,C27/D27,""),"") -> 432348.23 | P27: =IFERROR(IF(J27>0,M27/J27,""),"") -> 315271.42 | Q27: =IFERROR(IF(E27>0,D27/E27,""),"")
A28: 45953 | B28: T5 | C28: 43735282 | D28: 106 | G28: 7914946 | H28: 4136019 | I28: 2622403 | J28: 49 | K28: 1957600 | M28: =IF(SUM(G28:I28)>0,SUM(G28:I28),"") -> 14673368 | N28: =IF(N(C28)+N(M28)>0,N(C28)+N(M28),"") -> 58408650 | O28: =IFERROR(IF(D28>0,C28/D28,""),"") -> 412597 | P28: =IFERROR(IF(J28>0,M28/J28,""),"") -> 299456.49 | Q28: =IFERROR(IF(E28>0,D28/E28,""),"")
A29: 45954 | B29: T6 | C29: 47394192 | D29: 121 | G29: 6988414 | H29: 9919051 | I29: 2122731 | J29: 62 | K29: 259259 | M29: =IF(SUM(G29:I29)>0,SUM(G29:I29),"") -> 19030196 | N29: =IF(N(C29)+N(M29)>0,N(C29)+N(M29),"") -> 66424388 | O29: =IFERROR(IF(D29>0,C29/D29,""),"") -> 391687.54 | P29: =IFERROR(IF(J29>0,M29/J29,""),"") -> 306938.65 | Q29: =IFERROR(IF(E29>0,D29/E29,""),"")
A30: 45955 | B30: T7 | C30: 39190083 | D30: 98 | G30: 9397319 | H30: 7912539 | I30: 3912415 | J30: 91 | K30: 5492877 | M30: =IF(SUM(G30:I30)>0,SUM(G30:I30),"") -> 21222273 | N30: =IF(N(C30)+N(M30)>0,N(C30)+N(M30),"") -> 60412356 | O30: =IFERROR(IF(D30>0,C30/D30,""),"") -> 399898.81 | P30: =IFERROR(IF(J30>0,M30/J30,""),"") -> 233211.79 | Q30: =IFERROR(IF(E30>0,D30/E30,""),"")
A31: 45956 | B31: CN | C31: 29838803 | D31: 80 | G31: 8534055 | H31: 5791518 | I31: 2989530 | J31: 64 | K31: 296296 | M31: =IF(SUM(G31:I31)>0,SUM(G31:I31),"") -> 17315103 | N31: =IF(N(C31)+N(M31)>0,N(C31)+N(M31),"") -> 47153906 | O31: =IFERROR(IF(D31>0,C31/D31,""),"") -> 372985.04 | P31: =IFERROR(IF(J31>0,M31/J31,""),"") -> 270548.48 | Q31: =IFERROR(IF(E31>0,D31/E31,""),"")
A32: 45957 | B32: T2 | C32: 42781227 | D32: 93 | G32: 7607171 | H32: 5336011 | I32: 2195092 | J32: 50 | K32: 1622172 | M32: =IF(SUM(G32:I32)>0,SUM(G32:I32),"") -> 15138274 | N32: =IF(N(C32)+N(M32)>0,N(C32)+N(M32),"") -> 57919501 | O32: =IFERROR(IF(D32>0,C32/D32,""),"") -> 460013.19 | P32: =IFERROR(IF(J32>0,M32/J32,""),"") -> 302765.48 | Q32: =IFERROR(IF(E32>0,D32/E32,""),"")
A33: 45958 | B33: T3 | C33: 42127035 | D33: 87 | G33: 8714382 | H33: 5786008 | I33: 1874195 | J33: 53 | K33: 4551019 | M33: =IF(SUM(G33:I33)>0,SUM(G33:I33),"") -> 16374585 | N33: =IF(N(C33)+N(M33)>0,N(C33)+N(M33),"") -> 58501620 | O33: =IFERROR(IF(D33>0,C33/D33,""),"") -> 484218.79 | P33: =IFERROR(IF(J33>0,M33/J33,""),"") -> 308954.43 | Q33: =IFERROR(IF(E33>0,D33/E33,""),"")
A34: 45959 | B34: T4 | C34: 55797480 | D34: 110 | G34: 10340391 | H34: 7818001 | I34: 2247429 | J34: 78 | K34: 15734022 | M34: =IF(SUM(G34:I34)>0,SUM(G34:I34),"") -> 20405821 | N34: =IF(N(C34)+N(M34)>0,N(C34)+N(M34),"") -> 76203301 | O34: =IFERROR(IF(D34>0,C34/D34,""),"") -> 507249.82 | P34: =IFERROR(IF(J34>0,M34/J34,""),"") -> 261613.09 | Q34: =IFERROR(IF(E34>0,D34/E34,""),"")
A35: 45960 | B35: T5 | C35: 52517367 | D35: 127 | G35: 11386488 | H35: 4258011 | I35: 2307008 | J35: 70 | K35: 2536000 | M35: =IF(SUM(G35:I35)>0,SUM(G35:I35),"") -> 17951507 | N35: =IF(N(C35)+N(M35)>0,N(C35)+N(M35),"") -> 70468874 | O35: =IFERROR(IF(D35>0,C35/D35,""),"") -> 413522.57 | P35: =IFERROR(IF(J35>0,M35/J35,""),"") -> 256450.1 | Q35: =IFERROR(IF(E35>0,D35/E35,""),"")
A36: 45961 | B36: T6 | C36: 35890098 | D36: 100 | G36: 7876186 | H36: 3915025 | I36: 4457534 | J36: 70 | K36: 1028572 | M36: =IF(SUM(G36:I36)>0,SUM(G36:I36),"") -> 16248745 | N36: =IF(N(C36)+N(M36)>0,N(C36)+N(M36),"") -> 52138843 | O36: =IFERROR(IF(D36>0,C36/D36,""),"") -> 358900.98 | P36: =IFERROR(IF(J36>0,M36/J36,""),"") -> 232124.93 | Q36: =IFERROR(IF(E36>0,D36/E36,""),"")

Sheet 📅 DAILY T11-25
A1: DAILY INPUT • THÁNG 11/2025 • CARASE FB & STORE
A2: 🟡 Ô VÀNG = Team điền mỗi ngày | 🟢 Ô XANH = Tự tính | Deadline 22:00
A3: 📅 THỜI GIAN | C3: 📱 FACEBOOK | E3: 📢 ADS | G3: 🏪 STORE | K3: 👓 O3 | L3: 📝 | M3: 📊 AUTO | O3: 📊 AUTO | Q3: 📊
A4: Ngày | B4: T | C4: DT FB (đ) | D4: Đơn FB | E4: CMT+IB (Vpage) | F4: CP Ads (đ) | G4: DT NDC (đ) | H4: DT PH (đ) | I4: DT NGT (đ) | J4: Đơn Store | K4: DT O3 (đ) | L4: Ghi chú | M4: DT Store (=G+H+I) | N4: DT Total (=FB+Store) | O4: AOV FB (C/D) | P4: AOV Store (M/J) | Q4: CR% (D/E)
A5: TARGET/THÁNG
A6: 45962 | B6: T7 | C6: 47479052 | D6: 116 | G6: 9657531 | H6: 5461954 | I6: 2094151 | J6: 71 | K6: 1028800 | M6: =IF(SUM(G6:I6)>0,SUM(G6:I6),"") -> 17213636 | N6: =IF(N(C6)+N(M6)>0,N(C6)+N(M6),"") -> 64692688 | O6: =IFERROR(IF(D6>0,C6/D6,""),"") -> 409302.17 | P6: =IFERROR(IF(J6>0,M6/J6,""),"") -> 242445.58 | Q6: =IFERROR(IF(E6>0,D6/E6,""),"")
A7: 45963 | B7: CN | C7: 44821039 | D7: 90 | G7: 9507674 | H7: 2917006 | I7: 4138514 | J7: 59 | K7: 7380800 | M7: =IF(SUM(G7:I7)>0,SUM(G7:I7),"") -> 16563194 | N7: =IF(N(C7)+N(M7)>0,N(C7)+N(M7),"") -> 61384233 | O7: =IFERROR(IF(D7>0,C7/D7,""),"") -> 498011.54 | P7: =IFERROR(IF(J7>0,M7/J7,""),"") -> 280732.1 | Q7: =IFERROR(IF(E7>0,D7/E7,""),"")
A8: 45964 | B8: T2 | C8: 37521052 | D8: 91 | G8: 4192924 | H8: 1253011 | I8: 1699970 | J8: 26 | K8: 1256000 | M8: =IF(SUM(G8:I8)>0,SUM(G8:I8),"") -> 7145905 | N8: =IF(N(C8)+N(M8)>0,N(C8)+N(M8),"") -> 44666957 | O8: =IFERROR(IF(D8>0,C8/D8,""),"") -> 412319.25 | P8: =IFERROR(IF(J8>0,M8/J8,""),"") -> 274842.5 | Q8: =IFERROR(IF(E8>0,D8/E8,""),"")
A9: 45965 | B9: T3 | C9: 50467342 | D9: 111 | G9: 10944333 | H9: 5103957 | I9: 3439002 | J9: 60 | K9: 2463411 | M9: =IF(SUM(G9:I9)>0,SUM(G9:I9),"") -> 19487292 | N9: =IF(N(C9)+N(M9)>0,N(C9)+N(M9),"") -> 69954634 | O9: =IFERROR(IF(D9>0,C9/D9,""),"") -> 454660.74 | P9: =IFERROR(IF(J9>0,M9/J9,""),"") -> 324788.2 | Q9: =IFERROR(IF(E9>0,D9/E9,""),"")
A10: 45966 | B10: T4 | C10: 49212582 | D10: 118 | G10: 9454879 | H10: 5255018 | I10: 2162967 | J10: 66 | K10: 944973 | M10: =IF(SUM(G10:I10)>0,SUM(G10:I10),"") -> 16872864 | N10: =IF(N(C10)+N(M10)>0,N(C10)+N(M10),"") -> 66085446 | O10: =IFERROR(IF(D10>0,C10/D10,""),"") -> 417055.78 | P10: =IFERROR(IF(J10>0,M10/J10,""),"") -> 255649.45 | Q10: =IFERROR(IF(E10>0,D10/E10,""),"")
A11: 45967 | B11: T5 | C11: 60027007 | D11: 126 | G11: 11104091 | H11: 9389119 | I11: 4991001 | J11: 90 | K11: 814815 | M11: =IF(SUM(G11:I11)>0,SUM(G11:I11),"") -> 25484211 | N11: =IF(N(C11)+N(M11)>0,N(C11)+N(M11),"") -> 85511218 | O11: =IFERROR(IF(D11>0,C11/D11,""),"") -> 476404.82 | P11: =IFERROR(IF(J11>0,M11/J11,""),"") -> 283157.9 | Q11: =IFERROR(IF(E11>0,D11/E11,""),"")
A12: 45968 | B12: T6 | C12: 58404733 | D12: 153 | G12: 6636002 | H12: 7247511 | I12: 3067400 | J12: 73 | K12: 1560355 | M12: =IF(SUM(G12:I12)>0,SUM(G12:I12),"") -> 16950913 | N12: =IF(N(C12)+N(M12)>0,N(C12)+N(M12),"") -> 75355646 | O12: =IFERROR(IF(D12>0,C12/D12,""),"") -> 381730.28 | P12: =IFERROR(IF(J12>0,M12/J12,""),"") -> 232204.29 | Q12: =IFERROR(IF(E12>0,D12/E12,""),"")
A13: 45969 | B13: T7 | C13: 49122507 | D13: 130 | G13: 10064479 | H13: 11675253 | I13: 3642643 | J13: 101 | K13: 985767 | M13: =IF(SUM(G13:I13)>0,SUM(G13:I13),"") -> 25382375 | N13: =IF(N(C13)+N(M13)>0,N(C13)+N(M13),"") -> 74504882 | O13: =IFERROR(IF(D13>0,C13/D13,""),"") -> 377865.44 | P13: =IFERROR(IF(J13>0,M13/J13,""),"") -> 251310.64 | Q13: =IFERROR(IF(E13>0,D13/E13,""),"")
A14: 45970 | B14: CN | C14: 33572771 | D14: 92 | G14: 8721076 | H14: 3423006 | I14: 2801231 | J14: 68 | K14: 1714972 | M14: =IF(SUM(G14:I14)>0,SUM(G14:I14),"") -> 14945313 | N14: =IF(N(C14)+N(M14)>0,N(C14)+N(M14),"") -> 48518084 | O14: =IFERROR(IF(D14>0,C14/D14,""),"") -> 364921.42 | P14: =IFERROR(IF(J14>0,M14/J14,""),"") -> 219784.01 | Q14: =IFERROR(IF(E14>0,D14/E14,""),"")
A15: 45971 | B15: T2 | C15: 46977598 | D15: 112 | G15: 6171972 | H15: 3156024 | I15: 4083355 | J15: 58 | K15: 185185 | M15: =IF(SUM(G15:I15)>0,SUM(G15:I15),"") -> 13411351 | N15: =IF(N(C15)+N(M15)>0,N(C15)+N(M15),"") -> 60388949 | O15: =IFERROR(IF(D15>0,C15/D15,""),"") -> 419442.84 | P15: =IFERROR(IF(J15>0,M15/J15,""),"") -> 231230.19 | Q15: =IFERROR(IF(E15>0,D15/E15,""),"")
A16: 45972 | B16: T3 | C16: 56799581 | D16: 132 | G16: 13151171 | H16: 8384742 | I16: 4054912 | J16: 68 | K16: 2635200 | M16: =IF(SUM(G16:I16)>0,SUM(G16:I16),"") -> 25590825 | N16: =IF(N(C16)+N(M16)>0,N(C16)+N(M16),"") -> 82390406 | O16: =IFERROR(IF(D16>0,C16/D16,""),"") -> 430299.86 | P16: =IFERROR(IF(J16>0,M16/J16,""),"") -> 376335.66 | Q16: =IFERROR(IF(E16>0,D16/E16,""),"")
A17: 45973 | B17: T4 | C17: 47954694 | D17: 102 | G17: 6815983 | H17: 5357012 | I17: 3774543 | J17: 60 | K17: 8266438 | M17: =IF(SUM(G17:I17)>0,SUM(G17:I17),"") -> 15947538 | N17: =IF(N(C17)+N(M17)>0,N(C17)+N(M17),"") -> 63902232 | O17: =IFERROR(IF(D17>0,C17/D17,""),"") -> 470144.06 | P17: =IFERROR(IF(J17>0,M17/J17,""),"") -> 265792.3 | Q17: =IFERROR(IF(E17>0,D17/E17,""),"")
... A26: 45982 | B26: T6 | C26: 49924577 | D26: 118 | G26: 11050962 | H26: 9479029 | I26: 3975110 | J26: 94 | K26: 2887619 | M26: =IF(SUM(G26:I26)>0,SUM(G26:I26),"") -> 24505101 | N26: =IF(N(C26)+N(M26)>0,N(C26)+N(M26),"") -> 74429678 | O26: =IFERROR(IF(D26>0,C26/D26,""),"") -> 423089.64 | P26: =IFERROR(IF(J26>0,M26/J26,""),"") -> 260692.56 | Q26: =IFERROR(IF(E26>0,D26/E26,""),"")
A27: 45983 | B27: T7 | C27: 34397955 | D27: 92 | G27: 11895164 | H27: 3951009 | I27: 4188385 | J27: 90 | M27: =IF(SUM(G27:I27)>0,SUM(G27:I27),"") -> 20034558 | N27: =IF(N(C27)+N(M27)>0,N(C27)+N(M27),"") -> 54432513 | O27: =IFERROR(IF(D27>0,C27/D27,""),"") -> 373890.82 | P27: =IFERROR(IF(J27>0,M27/J27,""),"") -> 222606.2 | Q27: =IFERROR(IF(E27>0,D27/E27,""),"")
A28: 45984 | B28: CN | C28: 34989519 | D28: 85 | G28: 14327436 | H28: 3550015 | I28: 4095413 | J28: 81 | K28: 629600 | M28: =IF(SUM(G28:I28)>0,SUM(G28:I28),"") -> 21972864 | N28: =IF(N(C28)+N(M28)>0,N(C28)+N(M28),"") -> 56962383 | O28: =IFERROR(IF(D28>0,C28/D28,""),"") -> 411641.4 | P28: =IFERROR(IF(J28>0,M28/J28,""),"") -> 271269.93 | Q28: =IFERROR(IF(E28>0,D28/E28,""),"")
A29: 45985 | B29: T2 | C29: 44241336 | D29: 88 | G29: 8497514 | H29: 4962016 | I29: 4671301 | J29: 61 | K29: 7711141 | M29: =IF(SUM(G29:I29)>0,SUM(G29:I29),"") -> 18130831 | N29: =IF(N(C29)+N(M29)>0,N(C29)+N(M29),"") -> 62372167 | O29: =IFERROR(IF(D29>0,C29/D29,""),"") -> 502742.45 | P29: =IFERROR(IF(J29>0,M29/J29,""),"") -> 297226.74 | Q29: =IFERROR(IF(E29>0,D29/E29,""),"")
A30: 45986 | B30: T3 | C30: 64843824 | D30: 137 | G30: 7114980 | H30: 4628024 | I30: 4863072 | J30: 67 | K30: 4251200 | M30: =IF(SUM(G30:I30)>0,SUM(G30:I30),"") -> 16606076 | N30: =IF(N(C30)+N(M30)>0,N(C30)+N(M30),"") -> 81449900 | O30: =IFERROR(IF(D30>0,C30/D30,""),"") -> 473312.58 | P30: =IFERROR(IF(J30>0,M30/J30,""),"") -> 247851.88 | Q30: =IFERROR(IF(E30>0,D30/E30,""),"")
A31: 45987 | B31: T4 | C31: 45696695 | D31: 119 | G31: 14793011 | H31: 7416341 | I31: 4042941 | J31: 85 | K31: 502400 | M31: =IF(SUM(G31:I31)>0,SUM(G31:I31),"") -> 26252293 | N31: =IF(N(C31)+N(M31)>0,N(C31)+N(M31),"") -> 71948988 | O31: =IFERROR(IF(D31>0,C31/D31,""),"") -> 384005.84 | P31: =IFERROR(IF(J31>0,M31/J31,""),"") -> 308850.51 | Q31: =IFERROR(IF(E31>0,D31/E31,""),"")
A32: 45988 | B32: T5 | C32: 60753329 | D32: 158 | G32: 17658520 | H32: 4878001 | I32: 4975380 | J32: 94 | K32: 1352874 | M32: =IF(SUM(G32:I32)>0,SUM(G32:I32),"") -> 27511901 | N32: =IF(N(C32)+N(M32)>0,N(C32)+N(M32),"") -> 88265230 | O32: =IFERROR(IF(D32>0,C32/D32,""),"") -> 384514.74 | P32: =IFERROR(IF(J32>0,M32/J32,""),"") -> 292679.8 | Q32: =IFERROR(IF(E32>0,D32/E32,""),"")
A33: 45989 | B33: T6 | C33: 62827222 | D33: 145 | G33: 17413291 | H33: 9434058 | I33: 7139249 | J33: 115 | K33: 6860979 | M33: =IF(SUM(G33:I33)>0,SUM(G33:I33),"") -> 33986598 | N33: =IF(N(C33)+N(M33)>0,N(C33)+N(M33),"") -> 96813820 | O33: =IFERROR(IF(D33>0,C33/D33,""),"") -> 433291.19 | P33: =IFERROR(IF(J33>0,M33/J33,""),"") -> 295535.63 | Q33: =IFERROR(IF(E33>0,D33/E33,""),"")
A34: 45990 | B34: T7 | C34: 56163940 | D34: 150 | G34: 12169877 | H34: 8166029 | I34: 5901888 | J34: 116 | K34: 2136281 | M34: =IF(SUM(G34:I34)>0,SUM(G34:I34),"") -> 26237794 | N34: =IF(N(C34)+N(M34)>0,N(C34)+N(M34),"") -> 82401734 | O34: =IFERROR(IF(D34>0,C34/D34,""),"") -> 374426.27 | P34: =IFERROR(IF(J34>0,M34/J34,""),"") -> 226187.88 | Q34: =IFERROR(IF(E34>0,D34/E34,""),"")
A35: 45991 | B35: CN | C35: 45037191 | D35: 113 | G35: 13629146 | H35: 4748004 | I35: 2738968 | J35: 78 | K35: 138889 | M35: =IF(SUM(G35:I35)>0,SUM(G35:I35),"") -> 21116118 | N35: =IF(N(C35)+N(M35)>0,N(C35)+N(M35),"") -> 66153309 | O35: =IFERROR(IF(D35>0,C35/D35,""),"") -> 398559.21 | P35: =IFERROR(IF(J35>0,M35/J35,""),"") -> 270719.46 | Q35: =IFERROR(IF(E35>0,D35/E35,""),"")

Sheet 📅 DAILY T12-25
A1: DAILY INPUT • THÁNG 12/2025 • CARASE FB & STORE
A2: 🟡 Ô VÀNG = Team điền mỗi ngày | 🟢 Ô XANH = Tự tính | Deadline 22:00
A3: 📅 THỜI GIAN | C3: 📱 FACEBOOK | E3: 📢 ADS | G3: 🏪 STORE | K3: 👓 O3 | L3: 📝 | M3: 📊 AUTO | O3: 📊 AUTO | Q3: 📊
A4: Ngày | B4: T | C4: DT FB (đ) | D4: Đơn FB | E4: CMT+IB (Vpage) | F4: CP Ads (đ) | G4: DT NDC (đ) | H4: DT PH (đ) | I4: DT NGT (đ) | J4: Đơn Store | K4: DT O3 (đ) | L4: Ghi chú | M4: DT Store (=G+H+I) | N4: DT Total (=FB+Store) | O4: AOV FB (C/D) | P4: AOV Store (M/J) | Q4: CR% (D/E)
A5: TARGET/THÁNG
A6: 45992 | B6: T2 | C6: 45020711 | D6: 86 | G6: 6040002 | H6: 2779005 | I6: 1577438 | J6: 42 | K6: 10475495 | M6: =IF(SUM(G6:I6)>0,SUM(G6:I6),"") -> 10396445 | N6: =IF(N(C6)+N(M6)>0,N(C6)+N(M6),"") -> 55417156 | O6: =IFERROR(IF(D6>0,C6/D6,""),"") -> 523496.64 | P6: =IFERROR(IF(J6>0,M6/J6,""),"") -> 247534.4 | Q6: =IFERROR(IF(E6>0,D6/E6,""),"")
A7: 45993 | B7: T3 | C7: 53475125 | D7: 121 | G7: 11543936 | H7: 2448018 | I7: 2999915 | J7: 54 | K7: 3200000 | M7: =IF(SUM(G7:I7)>0,SUM(G7:I7),"") -> 16991869 | N7: =IF(N(C7)+N(M7)>0,N(C7)+N(M7),"") -> 70466994 | O7: =IFERROR(IF(D7>0,C7/D7,""),"") -> 441943.18 | P7: =IFERROR(IF(J7>0,M7/J7,""),"") -> 314664.24 | Q7: =IFERROR(IF(E7>0,D7/E7,""),"")
A8: 45994 | B8: T4 | C8: 52732636 | D8: 117 | G8: 7441507 | H8: 4226023 | I8: 4348011 | J8: 61 | K8: 2171200 | M8: =IF(SUM(G8:I8)>0,SUM(G8:I8),"") -> 16015541 | N8: =IF(N(C8)+N(M8)>0,N(C8)+N(M8),"") -> 68748177 | O8: =IFERROR(IF(D8>0,C8/D8,""),"") -> 450706.29 | P8: =IFERROR(IF(J8>0,M8/J8,""),"") -> 262549.85 | Q8: =IFERROR(IF(E8>0,D8/E8,""),"")
A9: 45995 | B9: T5 | C9: 44254621 | D9: 98 | G9: 14201097 | H9: 5686012 | I9: 3045926 | J9: 91 | K9: 551037 | M9: =IF(SUM(G9:I9)>0,SUM(G9:I9),"") -> 22933035 | N9: =IF(N(C9)+N(M9)>0,N(C9)+N(M9),"") -> 67187656 | O9: =IFERROR(IF(D9>0,C9/D9,""),"") -> 451577.77 | P9: =IFERROR(IF(J9>0,M9/J9,""),"") -> 252011.37 | Q9: =IFERROR(IF(E9>0,D9/E9,""),"")
A10: 45996 | B10: T6 | C10: 48002681 | D10: 116 | G10: 13714286 | H10: 7682027 | I10: 4757941 | J10: 99 | K10: 4274972 | M10: =IF(SUM(G10:I10)>0,SUM(G10:I10),"") -> 26154254 | N10: =IF(N(C10)+N(M10)>0,N(C10)+N(M10),"") -> 74156935 | O10: =IFERROR(IF(D10>0,C10/D10,""),"") -> 413816.22 | P10: =IFERROR(IF(J10>0,M10/J10,""),"") -> 264184.38 | Q10: =IFERROR(IF(E10>0,D10/E10,""),"")
A11: 45997 | B11: T7 | C11: 38647128 | D11: 95 | G11: 14455707 | H11: 11348542 | I11: 8723830 | J11: 136 | K11: 1857600 | M11: =IF(SUM(G11:I11)>0,SUM(G11:I11),"") -> 34528079 | N11: =IF(N(C11)+N(M11)>0,N(C11)+N(M11),"") -> 73175207 | O11: =IFERROR(IF(D11>0,C11/D11,""),"") -> 406811.87 | P11: =IFERROR(IF(J11>0,M11/J11,""),"") -> 253882.93 | Q11: =IFERROR(IF(E11>0,D11/E11,""),"")
A12: 45998 | B12: CN | C12: 41728875 | D12: 112 | G12: 14353575 | H12: 6256016 | I12: 3840130 | J12: 86 | K12: 1244340 | M12: =IF(SUM(G12:I12)>0,SUM(G12:I12),"") -> 24449721 | N12: =IF(N(C12)+N(M12)>0,N(C12)+N(M12),"") -> 66178596 | O12: =IFERROR(IF(D12>0,C12/D12,""),"") -> 372579.24 | P12: =IFERROR(IF(J12>0,M12/J12,""),"") -> 284299.08 | Q12: =IFERROR(IF(E12>0,D12/E12,""),"")
A13: 45999 | B13: T2 | C13: 33332635 | D13: 70 | G13: 10259014 | H13: 6904555 | I13: 1594281 | J13: 55 | K13: 7472458 | M13: =IF(SUM(G13:I13)>0,SUM(G13:I13),"") -> 18757850 | N13: =IF(N(C13)+N(M13)>0,N(C13)+N(M13),"") -> 52090485 | O13: =IFERROR(IF(D13>0,C13/D13,""),"") -> 476180.5 | P13: =IFERROR(IF(J13>0,M13/J13,""),"") -> 341051.82 | Q13: =IFERROR(IF(E13>0,D13/E13,""),"")
A14: 46000 | B14: T3 | C14: 56618375 | D14: 116 | G14: 17487196 | H14: 4983015 | I14: 2586169 | J14: 85 | K14: 686400 | M14: =IF(SUM(G14:I14)>0,SUM(G14:I14),"") -> 25056380 | N14: =IF(N(C14)+N(M14)>0,N(C14)+N(M14),"") -> 81674755 | O14: =IFERROR(IF(D14>0,C14/D14,""),"") -> 488089.44 | P14: =IFERROR(IF(J14>0,M14/J14,""),"") -> 294780.94 | Q14: =IFERROR(IF(E14>0,D14/E14,""),"")
A15: 46001 | B15: T4 | C15: 47094926 | D15: 113 | G15: 11865091 | H15: 9099536 | I15: 4065185 | J15: 79 | K15: 555559 | M15: =IF(SUM(G15:I15)>0,SUM(G15:I15),"") -> 25029812 | N15: =IF(N(C15)+N(M15)>0,N(C15)+N(M15),"") -> 72124738 | O15: =IFERROR(IF(D15>0,C15/D15,""),"") -> 416769.26 | P15: =IFERROR(IF(J15>0,M15/J15,""),"") -> 316833.06 | Q15: =IFERROR(IF(E15>0,D15/E15,""),"")
A16: 46002 | B16: T5 | C16: 51119403 | D16: 116 | G16: 15286488 | H16: 6212016 | I16: 5758149 | J16: 95 | K16: 3017039 | M16: =IF(SUM(G16:I16)>0,SUM(G16:I16),"") -> 27256653 | N16: =IF(N(C16)+N(M16)>0,N(C16)+N(M16),"") -> 78376056 | O16: =IFERROR(IF(D16>0,C16/D16,""),"") -> 440684.51 | P16: =IFERROR(IF(J16>0,M16/J16,""),"") -> 286912.14 | Q16: =IFERROR(IF(E16>0,D16/E16,""),"")
A17: 46003 | B17: T6 | C17: 53829137 | D17: 143 | G17: 14987854 | H17: 6453357 | I17: 5763081 | J17: 93 | K17: 1301096 | M17: =IF(SUM(G17:I17)>0,SUM(G17:I17),"") -> 27204292 | N17: =IF(N(C17)+N(M17)>0,N(C17)+N(M17),"") -> 81033429 | O17: =IFERROR(IF(D17>0,C17/D17,""),"") -> 376427.53 | P17: =IFERROR(IF(J17>0,M17/J17,""),"") -> 292519.27 | Q17: =IFERROR(IF(E17>0,D17/E17,""),"")
